package java05_exception;

public class ExceptionTest4 {
	int n1;
	int n2;
	public ExceptionTest4() {		
	}
	public ExceptionTest4(int n1, int n2) throws ArithmeticException{
		this.n1 = n1;
		this.n2 = n2;
		plus();
	}
	public void plus() throws ArithmeticException{
		System.out.println("n1+n2="+ (n1+n2));
		minus();
	}
	public void minus() throws ArithmeticException{
		System.out.println("n1-n2="+ (n1-n2));
		int data = Integer.valueOf("천이백");
		multiple();
	}
	public void multiple() throws ArithmeticException{
		System.out.println("n1*n2="+ n1*n2);
		devide();
	}
	public void devide() throws ArithmeticException{
		System.out.println("n1/n2="+ n1/n2); // ArithmeticException
	}
	public static void main(String[] a) {
		try {
			new ExceptionTest4(100,0);
		}catch(ArithmeticException e) {
			System.out.println("예외가 발생하였습니다.");
		}
	}
}







